Workbook

Sheet Dashboard
B3: APEX Automotives FP&A Forecast Dashboard | P3: Selected Scenario: | S3: =IF(Forecast_Model!D5=1,Assumptions!C37,IF(Forecast_Model!D5=2,Assumptions!C38,IF(Forecast_Model!D5=3,Assumptions!C39,0))) -> Severe
B5: 24 Month Actuals & Forecast | Jan-26 to Dec-27
B7: KPI
C10: Revenue (£bn) | E10: Operating Profit (£bn) | H10: Operating Margin (%) | L10: Contribution margin (%) | P10: Units Sold | S10: Average Selling Price (£)
C14: =SUM(Forecast_Model!E32:AB32) -> 10649581200 | E14: =SUM(Forecast_Model!E36:AB36) -> -5.4882434e+08 | H14: =E14/C14 -> -0.051534828 | M14: =(SUM(Forecast_Model!E32:AB32)-SUM(Forecast_Model!E30:AB30))/SUM(Forecast_Model!E32:AB32) -> 0.31945685 | P14: =SUM(Forecast_Model!E19:AB19) -> 372230 | S14: =SUM(Forecast_Model!E32:AB32)/SUM(Forecast_Model!E19:AB19) -> 28610.217
B17: Performance Trends
E19: Revenue Trend | P19: Operating Profit Trend
B41: Scenario & Performance Analysis
E43: Dashboard: Operating Margin | P43: Revenue By Scenario

Sheet Assumptions
B2: Assumptions
B6: Base Monthly Manufactured Units | C6: 20000
B7: Base ASP (£) | C7: 30000
B9: Raw Material per Unit | C9: 16500
B10: Labour Per Unit | C10: 750
B11: Other Variable per Unit | C11: 1250
B13: Fixed Cost (Monthly) | C13: 160000000
B15: Assumed Inflation Index | C15: Annually | D15: Monthly | E15: Quarterly
B16: Raw Material | C16: 0.06 | D16: =(1+C16)^(1/12)-1 -> 0.0048675506 | E16: =(1+$C16)^(1/4)-1 -> 0.014673846
B17: Labour | C17: 0.05 | D17: =(1+C17)^(1/12)-1 -> 0.0040741238 | E17: =(1+$C17)^(1/4)-1 -> 0.012272234
B18: Other Variable | C18: 0.03 | D18: =(1+C18)^(1/12)-1 -> 0.0024662698 | E18: =(1+$C18)^(1/4)-1 -> 0.0074170718
B19: ASP Annual Growth | C19: 0.02 | D19: =(1+C19)^(1/12)-1 -> 0.0016515813 | E19: =(1+$C19)^(1/4)-1 -> 0.0049629316
B20: Fixed Cost Inflation | C20: 0.03 | D20: =(1+C20)^(1/12)-1 -> 0.0024662698 | E20: =(1+$C20)^(1/4)-1 -> 0.0074170718
B24: Scenario & Recovery Assumptions | D24: Moderate | E24: Severe
B26: Volume Shock | D26: -0.15 | E26: -0.3
B27: ASP Shock | D27: -0.05 | E27: -0.1
B28: Shock Start Month | D28: 46204 | E28: 46174
B29: Shock End Month | D29: 46357 | E29: 46447
B30: Volume Recovery/ Month | D30: 0.01 | E30: 0.006
B31: ASP Recovery/ Month | D31: 0.01 | E31: 0.01
B35: Selected Scenarios | D35: Affected Months:
B37: 1 | C37: Base | D37: Unchanged
B38: 2 | C38: Moderate | D38: Months 7-12
B39: 3 | C39: Severe | D39: Months 6-15

Sheet Forecast_Model
C2: 24 Month Forecast
C5: ="Selected Scenario: "& IF(D5=1,Assumptions!C37,IF(Forecast_Model!D5=2,Assumptions!C38,IF(Forecast_Model!D5=3,Assumptions!C39,0))) -> Selected Scenario: Severe | D5: 3
C6: Affected Months: | D6: =IF(D5=1,Assumptions!D37,IF(Forecast_Model!D5=2,Assumptions!D38,IF(Forecast_Model!D5=3,Assumptions!D39,0))) -> Months 6-15
C7: Currency | D7: GBP (£)
E11: =YEAR(E13) -> 2026 | F11: =YEAR(F13) -> 2026 | G11: =YEAR(G13) -> 2026 | H11: =YEAR(H13) -> 2026 | I11: =YEAR(I13) -> 2026 | J11: =YEAR(J13) -> 2026 | K11: =YEAR(K13) -> 2026 | L11: =YEAR(L13) -> 2026 | ... AB11: =YEAR(AB13) -> 2027
E12: =CHOOSE(MONTH(E13),1,1,1,2,2,2,3,3,3,4,4,4) -> 1 | F12: =CHOOSE(MONTH(F13),1,1,1,2,2,2,3,3,3,4,4,4) -> 1 | G12: =CHOOSE(MONTH(G13),1,1,1,2,2,2,3,3,3,4,4,4) -> 1 | H12: =CHOOSE(MONTH(H13),1,1,1,2,2,2,3,3,3,4,4,4) -> 2 | I12: =CHOOSE(MONTH(I13),1,1,1,2,2,2,3,3,3,4,4,4) -> 2 | J12: =CHOOSE(MONTH(J13),1,1,1,2,2,2,3,3,3,4,4,4) -> 2 | K12: =CHOOSE(MONTH(K13),1,1,1,2,2,2,3,3,3,4,4,4) -> 3 | L12: =CHOOSE(MONTH(L13),1,1,1,2,2,2,3,3,3,4,4,4) -> 3 | ... AB12: =CHOOSE(MONTH(AB13),1,1,1,2,2,2,3,3,3,4,4,4) -> 4
E13: 46053 | F13: =EOMONTH(E13,1) -> 46081 | G13: =EOMONTH(F13,1) -> 46112 | H13: =EOMONTH(G13,1) -> 46142 | I13: =EOMONTH(H13,1) -> 46173 | J13: =EOMONTH(I13,1) -> 46203 | K13: =EOMONTH(J13,1) -> 46234 | L13: =EOMONTH(K13,1) -> 46265 | M13: =EOMONTH(L13,1) -> 46295 | ... AB13: =EOMONTH(AA13,1) -> 46752
E14: 1 | F14: 2 | G14: 3 | H14: 4 | I14: 5 | J14: 6 | K14: 7 | L14: 8 | M14: 9 | N14: 10 | O14: 11 | P14: 12 | Q14: 13 | R14: 14 | S14: 15 | T14: 16 | U14: 17 | V14: 18 | W14: 19 | X14: 20 | Y14: 21 | Z14: 22 | AA14: 23 | AB14: 24
C15: Actuals (☑️)/ Forecast | E15: 1 | F15: 1 | G15: 1 | H15: 0 | I15: 0 | J15: 0 | K15: 0 | L15: 0 | M15: 0 | N15: 0 | O15: 0 | P15: 0 | Q15: 0 | R15: 0 | S15: 0 | T15: 0 | U15: 0 | V15: 0 | W15: 0 | X15: 0 | Y15: 0 | Z15: 0 | AA15: 0 | AB15: 0
C17: Base Units | E17: 19720 | F17: 21230 | G17: 19880 | H17: =Assumptions!$C$6 -> 20000 | I17: =Assumptions!$C$6 -> 20000 | J17: =Assumptions!$C$6 -> 20000 | K17: =Assumptions!$C$6 -> 20000 | L17: =Assumptions!$C$6 -> 20000 | M17: =Assumptions!$C$6 -> 20000 | N17: =Assumptions!$C$6 -> 20000 | O17: =Assumptions!$C$6 -> 20000 | ... AB17: =Assumptions!$C$6 -> 20000
C18: Volume Adjustment % | E18: =IF(Forecast_Model!$D$5=1,0%,IF(Forecast_Model!$D$5=2,IF(AND(E$14>=7,E$14<=12),Assumptions!$D$26,IF(E14>=13,MIN(0%,D18+Assumptions!$D$30),0%)),IF(Forecast_Model!$D$5=3,IF(AND(E$14>=6,E$14<=15),Assumptions!$E$26, IF(E14>=16,MIN(0%,D18+Assumptions!$E$30),0%)), 0%))) -> 0 | F18: =IF(Forecast_Model!$D$5=1,0%,IF(Forecast_Model!$D$5=2,IF(AND(F$14>=7,F$14<=12),Assumptions!$D$26,IF(F14>=13,MIN(0%,E18+Assumptions!$D$30),0%)),IF(Forecast_Model!$D$5=3,IF(AND(F$14>=6,F$14<=15),Assumptions!$E$26, IF(F14>=16,MIN(0%,E18+Assumptions!$E$30),0%)), 0%))) -> 0 | G18: =IF(Forecast_Model!$D$5=1,0%,IF(Forecast_Model!$D$5=2,IF(AND(G$14>=7,G$14<=12),Assumptions!$D$26,IF(G14>=13,MIN(0%,F18+Assumptions!$D$30),0%)),IF(Forecast_Model!$D$5=3,IF(AND(G$14>=6,G$14<=15),Assumptions!$E$26, IF(G14>=16,MIN(0%,F18+Assumptions!$E$30),0%)), 0%))) -> 0 | H18: =IF(Forecast_Model!$D$5=1,0%,IF(Forecast_Model!$D$5=2,IF(AND(H$14>=7,H$14<=12),Assumptions!$D$26,IF(H14>=13,MIN(0%,G18+Assumptions!$D$30),0%)),IF(Forecast_Model!$D$5=3,IF(AND(H$14>=6,H$14<=15),Assumptions!$E$26, IF(H14>=16,MIN(0%,G18+Assumptions!$E$30),0%)), 0%))) -> 0 | I18: =IF(Forecast_Model!$D$5=1,0%,IF(Forecast_Model!$D$5=2,IF(AND(I$14>=7,I$14<=12),Assumptions!$D$26,IF(I14>=13,MIN(0%,H18+Assumptions!$D$30),0%)),IF(Forecast_Model!$D$5=3,IF(AND(I$14>=6,I$14<=15),Assumptions!$E$26, IF(I14>=16,MIN(0%,H18+Assumptions!$E$30),0%)), 0%))) -> 0 | J18: =IF(Forecast_Model!$D$5=1,0%,IF(Forecast_Model!$D$5=2,IF(AND(J$14>=7,J$14<=12),Assumptions!$D$26,IF(J14>=13,MIN(0%,I18+Assumptions!$D$30),0%)),IF(Forecast_Model!$D$5=3,IF(AND(J$14>=6,J$14<=15),Assumptions!$E$26, IF(J14>=16,MIN(0%,I18+Assumptions!$E$30),0%)), 0%))) -> -0.3 | K18: =IF(Forecast_Model!$D$5=1,0%,IF(Forecast_Model!$D$5=2,IF(AND(K$14>=7,K$14<=12),Assumptions!$D$26,IF(K14>=13,MIN(0%,J18+Assumptions!$D$30),0%)),IF(Forecast_Model!$D$5=3,IF(AND(K$14>=6,K$14<=15),Assumptions!$E$26, IF(K14>=16,MIN(0%,J18+Assumptions!$E$30),0%)), 0%))) -> -0.3 | L18: =IF(Forecast_Model!$D$5=1,0%,IF(Forecast_Model!$D$5=2,IF(AND(L$14>=7,L$14<=12),Assumptions!$D$26,IF(L14>=13,MIN(0%,K18+Assumptions!$D$30),0%)),IF(Forecast_Model!$D$5=3,IF(AND(L$14>=6,L$14<=15),Assumptions!$E$26, IF(L14>=16,MIN(0%,K18+Assumptions!$E$30),0%)), 0%))) -> -0.3 | ... AB18: =IF(Forecast_Model!$D$5=1,0%,IF(Forecast_Model!$D$5=2,IF(AND(AB$14>=7,AB$14<=12),Assumptions!$D$26,IF(AB14>=13,MIN(0%,AA18+Assumptions!$D$30),0%)),IF(Forecast_Model!$D$5=3,IF(AND(AB$14>=6,AB$14<=15),Assumptions!$E$26, IF(AB14>=16,MIN(0%,AA18+Assumptions!$E$30),0%)), 0%))) -> -0.246
C19: Actual Units | E19: =E17*(1+E18) -> 19720 | F19: =F17*(1+F18) -> 21230 | G19: =G17*(1+G18) -> 19880 | H19: =H17*(1+H18) -> 20000 | I19: =I17*(1+I18) -> 20000 | J19: =J17*(1+J18) -> 14000 | K19: =K17*(1+K18) -> 14000 | L19: =L17*(1+L18) -> 14000 | ... AB19: =AB17*(1+AB18) -> 15080
C21: Base ASP | E21: =Assumptions!$C$7 -> 30000 | F21: =IF(MOD(MONTH(F13)-1,12)=0,(E21*(1+Assumptions!$C$19)),E21) -> 30000 | G21: =IF(MOD(MONTH(G13)-1,12)=0,(F21*(1+Assumptions!$C$19)),F21) -> 30000 | H21: =IF(MOD(MONTH(H13)-1,12)=0,(G21*(1+Assumptions!$C$19)),G21) -> 30000 | I21: =IF(MOD(MONTH(I13)-1,12)=0,(H21*(1+Assumptions!$C$19)),H21) -> 30000 | J21: =IF(MOD(MONTH(J13)-1,12)=0,(I21*(1+Assumptions!$C$19)),I21) -> 30000 | K21: =IF(MOD(MONTH(K13)-1,12)=0,(J21*(1+Assumptions!$C$19)),J21) -> 30000 | L21: =IF(MOD(MONTH(L13)-1,12)=0,(K21*(1+Assumptions!$C$19)),K21) -> 30000 | M21: =IF(MOD(MONTH(M13)-1,12)=0,(L21*(1+Assumptions!$C$19)),L21) -> 30000 | ... AB21: =IF(MOD(MONTH(AB13)-1,12)=0,(AA21*(1+Assumptions!$C$19)),AA21) -> 30600
C22: ASP Adj% | E22: =IF(Forecast_Model!$D$5=1,0%,IF(Forecast_Model!$D$5=2,IF(AND(E14>=7,E14<=12),Assumptions!$D$27,IF(E14>=13,MIN(0%,D22+Assumptions!$D$31),0%)),IF(Forecast_Model!$D$5=3,IF(AND(E14>=6,E14<=15),Assumptions!$E$27,IF(E14>=16,MIN(0%,D22+Assumptions!$E$31),0%))))) -> 0 | F22: =IF(Forecast_Model!$D$5=1,0%,IF(Forecast_Model!$D$5=2,IF(AND(F14>=7,F14<=12),Assumptions!$D$27,IF(F14>=13,MIN(0%,E22+Assumptions!$D$31),0%)),IF(Forecast_Model!$D$5=3,IF(AND(F14>=6,F14<=15),Assumptions!$E$27,IF(F14>=16,MIN(0%,E22+Assumptions!$E$31),0%))))) -> 0 | G22: =IF(Forecast_Model!$D$5=1,0%,IF(Forecast_Model!$D$5=2,IF(AND(G14>=7,G14<=12),Assumptions!$D$27,IF(G14>=13,MIN(0%,F22+Assumptions!$D$31),0%)),IF(Forecast_Model!$D$5=3,IF(AND(G14>=6,G14<=15),Assumptions!$E$27,IF(G14>=16,MIN(0%,F22+Assumptions!$E$31),0%))))) -> 0 | H22: =IF(Forecast_Model!$D$5=1,0%,IF(Forecast_Model!$D$5=2,IF(AND(H14>=7,H14<=12),Assumptions!$D$27,IF(H14>=13,MIN(0%,G22+Assumptions!$D$31),0%)),IF(Forecast_Model!$D$5=3,IF(AND(H14>=6,H14<=15),Assumptions!$E$27,IF(H14>=16,MIN(0%,G22+Assumptions!$E$31),0%))))) -> 0 | I22: =IF(Forecast_Model!$D$5=1,0%,IF(Forecast_Model!$D$5=2,IF(AND(I14>=7,I14<=12),Assumptions!$D$27,IF(I14>=13,MIN(0%,H22+Assumptions!$D$31),0%)),IF(Forecast_Model!$D$5=3,IF(AND(I14>=6,I14<=15),Assumptions!$E$27,IF(I14>=16,MIN(0%,H22+Assumptions!$E$31),0%))))) -> 0 | J22: =IF(Forecast_Model!$D$5=1,0%,IF(Forecast_Model!$D$5=2,IF(AND(J14>=7,J14<=12),Assumptions!$D$27,IF(J14>=13,MIN(0%,I22+Assumptions!$D$31),0%)),IF(Forecast_Model!$D$5=3,IF(AND(J14>=6,J14<=15),Assumptions!$E$27,IF(J14>=16,MIN(0%,I22+Assumptions!$E$31),0%))))) -> -0.1 | K22: =IF(Forecast_Model!$D$5=1,0%,IF(Forecast_Model!$D$5=2,IF(AND(K14>=7,K14<=12),Assumptions!$D$27,IF(K14>=13,MIN(0%,J22+Assumptions!$D$31),0%)),IF(Forecast_Model!$D$5=3,IF(AND(K14>=6,K14<=15),Assumptions!$E$27,IF(K14>=16,MIN(0%,J22+Assumptions!$E$31),0%))))) -> -0.1 | L22: =IF(Forecast_Model!$D$5=1,0%,IF(Forecast_Model!$D$5=2,IF(AND(L14>=7,L14<=12),Assumptions!$D$27,IF(L14>=13,MIN(0%,K22+Assumptions!$D$31),0%)),IF(Forecast_Model!$D$5=3,IF(AND(L14>=6,L14<=15),Assumptions!$E$27,IF(L14>=16,MIN(0%,K22+Assumptions!$E$31),0%))))) -> -0.1 | ... AB22: =IF(Forecast_Model!$D$5=1,0%,IF(Forecast_Model!$D$5=2,IF(AND(AB14>=7,AB14<=12),Assumptions!$D$27,IF(AB14>=13,MIN(0%,AA22+Assumptions!$D$31),0%)),IF(Forecast_Model!$D$5=3,IF(AND(AB14>=6,AB14<=15),Assumptions!$E$27,IF(AB14>=16,MIN(0%,AA22+Assumptions!$E$31),0%))))) -> -0.01
C23: Actual ASP | E23: =E21 * (1+E22) -> 30000 | F23: =F21 * (1+F22) -> 30000 | G23: =G21 * (1+G22) -> 30000 | H23: =H21 * (1+H22) -> 30000 | I23: =I21 * (1+I22) -> 30000 | J23: =J21 * (1+J22) -> 27000 | K23: =K21 * (1+K22) -> 27000 | L23: =L21 * (1+L22) -> 27000 | ... AB23: =AB21 * (1+AB22) -> 30294
C25: Raw Material / Unit | E25: =Assumptions!$C$9 -> 16500 | F25: =E25*(1+Assumptions!$D$16) -> 16580.315 | G25: =F25*(1+Assumptions!$D$16) -> 16661.02 | H25: =G25*(1+Assumptions!$D$16) -> 16742.118 | I25: =H25*(1+Assumptions!$D$16) -> 16823.612 | J25: =I25*(1+Assumptions!$D$16) -> 16905.501 | K25: =J25*(1+Assumptions!$D$16) -> 16987.79 | L25: =K25*(1+Assumptions!$D$16) -> 17070.479 | M25: =L25*(1+Assumptions!$D$16) -> 17153.57 | ... AB25: =AA25*(1+Assumptions!$D$16) -> 18449.596
C26: Labour / Unit | E26: =Assumptions!$C$10 -> 750 | F26: =E26 * (1+Assumptions!$D$17) -> 753.05559 | G26: =F26 * (1+Assumptions!$D$17) -> 756.12363 | H26: =G26 * (1+Assumptions!$D$17) -> 759.20418 | I26: =H26 * (1+Assumptions!$D$17) -> 762.29727 | J26: =I26 * (1+Assumptions!$D$17) -> 765.40296 | K26: =J26 * (1+Assumptions!$D$17) -> 768.52131 | L26: =K26 * (1+Assumptions!$D$17) -> 771.65236 | M26: =L26 * (1+Assumptions!$D$17) -> 774.79617 | ... AB26: =AA26 * (1+Assumptions!$D$17) -> 823.51988
C27: Other var / Unit | E27: =Assumptions!$C$11 -> 1250 | F27: =E27*(1+Assumptions!$D$18) -> 1253.0828 | G27: =F27*(1+Assumptions!$D$18) -> 1256.1733 | H27: =G27*(1+Assumptions!$D$18) -> 1259.2713 | I27: =H27*(1+Assumptions!$D$18) -> 1262.377 | J27: =I27*(1+Assumptions!$D$18) -> 1265.4904 | K27: =J27*(1+Assumptions!$D$18) -> 1268.6114 | L27: =K27*(1+Assumptions!$D$18) -> 1271.7402 | M27: =L27*(1+Assumptions!$D$18) -> 1274.8766 | ... AB27: =AA27*(1+Assumptions!$D$18) -> 1322.8625
C28: Total var/unit | E28: =SUM(E25:E27) -> 18500 | F28: =SUM(F25:F27) -> 18586.453 | G28: =SUM(G25:G27) -> 18673.317 | H28: =SUM(H25:H27) -> 18760.594 | I28: =SUM(I25:I27) -> 18848.286 | J28: =SUM(J25:J27) -> 18936.395 | K28: =SUM(K25:K27) -> 19024.922 | L28: =SUM(L25:L27) -> 19113.871 | ... AB28: =SUM(AB25:AB27) -> 20595.978
C30: Total Variable Cost | E30: =E19*E28 -> 364820000 | F30: =F19*F28 -> 3.945904e+08 | G30: =G19*G28 -> 3.7122554e+08 | H30: =H19*H28 -> 3.7521188e+08 | I30: =I19*I28 -> 3.7696572e+08 | J30: =J19*J28 -> 2.6510953e+08 | K30: =K19*K28 -> 2.6634891e+08 | L30: =L19*L28 -> 2.675942e+08 | ... AB30: =AB19*AB28 -> 3.1058735e+08
C32: Revenue | E32: =E19*E23 -> 591600000 | F32: =F19*F23 -> 636900000 | G32: =G19*G23 -> 596400000 | H32: =H19*H23 -> 600000000 | I32: =I19*I23 -> 600000000 | J32: =J19*J23 -> 378000000 | K32: =K19*K23 -> 378000000 | L32: =L19*L23 -> 378000000 | ... AB32: =AB19*AB23 -> 456833520
C33: Fixed Cost | E33: =Assumptions!$C$13 -> 160000000 | F33: =E33 * (1+Assumptions!$D$20) -> 1.603946e+08 | G33: =F33 * (1+Assumptions!$D$20) -> 1.6079018e+08 | H33: =G33 * (1+Assumptions!$D$20) -> 1.6118673e+08 | I33: =H33 * (1+Assumptions!$D$20) -> 1.6158426e+08 | J33: =I33 * (1+Assumptions!$D$20) -> 1.6198277e+08 | K33: =J33 * (1+Assumptions!$D$20) -> 1.6238227e+08 | L33: =K33 * (1+Assumptions!$D$20) -> 1.6278274e+08 | M33: =L33 * (1+Assumptions!$D$20) -> 1.6318421e+08 | ... AB33: =AA33 * (1+Assumptions!$D$20) -> 1.693264e+08
C35: Contribution Profit | E35: =E32-E30 -> 226780000 | F35: =F32-F30 -> 2.423096e+08 | G35: =G32-G30 -> 2.2517446e+08 | H35: =H32-H30 -> 2.2478812e+08 | I35: =I32-I30 -> 2.2303428e+08 | J35: =J32-J30 -> 1.1289047e+08 | K35: =K32-K30 -> 1.1165109e+08 | L35: =L32-L30 -> 1.104058e+08 | ... AB35: =AB32-AB30 -> 1.4624617e+08
C36: Operating Profit | E36: =E32-E30-E33 -> 66780000 | F36: =F32-F30-F33 -> 81914999 | G36: =G32-G30-G33 -> 64384278 | H36: =H32-H30-H33 -> 63601389 | I36: =I32-I30-I33 -> 61450021 | J36: =J32-J30-J33 -> -49092298 | K36: =K32-K30-K33 -> -50731180 | L36: =L32-L30-L33 -> -52376940 | ... AB36: =AB32-AB30-AB33 -> -23080224
C37: Operating Margin % | E37: =E36/E32 -> 0.11288032 | F37: =F36/F32 -> 0.12861517 | G37: =G36/G32 -> 0.10795486 | H37: =H36/H32 -> 0.10600231 | I37: =I36/I32 -> 0.1024167 | J37: =J36/J32 -> -0.1298738 | K37: =K36/K32 -> -0.13420947 | L37: =L36/L32 -> -0.13856333 | ... AB37: =AB36/AB32 -> -0.050522176
C38: Contribution Margin % | E38: =(E32-E30)/E32 -> 0.38333333 | F38: =(F32-F30)/F32 -> 0.38045157 | G38: =(G32-G30)/G32 -> 0.3775561 | H38: =(H32-H30)/H32 -> 0.37464687 | I38: =(I32-I30)/I32 -> 0.3717238 | J38: =(J32-J30)/J32 -> 0.29865205 | K38: =(K32-K30)/K32 -> 0.29537324 | L38: =(L32-L30)/L32 -> 0.29207884 | ... AB38: =(AB32-AB30)/AB32 -> 0.32013012
C45: Contribution Metric
E47: Base Scenario (Year 2) | F47: Severe Scenario (Year 2) | G47: Base Scenario (24M) | H47: Severe Scenario (24M)
C48: Contribution Analysis
C49: Total Revenue | E49: 7344000000 | F49: 4978681200 | G49: 14568900000 | H49: 10649581200
C50: Total variable Cost | E50: 4.8183388e+09 | F50: 3.4826849e+09 | G50: 9.3897253e+09 | H50: 7.2474996e+09
C51: Total Units sold | E51: 240000 | F51: 173400 | G51: 480830 | H51: 372230
C53: CM Per unit | E53: =(E49-E50)/E51 -> 10523.588 | F53: =(F49-F50)/F51 -> 8627.4295 | G53: =(G49-G50)/G51 -> 10771.322 | H53: =(H49-H50)/H51 -> 9139.7299
C60: KPI Dashboard
E62: Month 1 | F62: Month 24 | G62: Change | H62: Change (bps)
C63: Growth
C64: Revenue Growth | E64: =E32 -> 591600000 | F64: =AB32 -> 456833520 | G64: =(F64-E64)/E64 -> -0.2278 | H64: -
C65: ASP Growth | E65: =E23 -> 30000 | F65: =AB23 -> 30294 | G65: =(F65-E65)/E65 -> 0.0098 | H65: -
C67: Profitability
C68: Operating Margin % | E68: =E36/E32 -> 0.11288032 | F68: =AB36/AB32 -> -0.050522176 | G68: =(F68-E68)/E68 -> -1.4475729 | H68: =(F68-E68)*10000 -> -1634.025
...

Sheet Graphs
C3: Dashboard: Revenue | M3: Dashboard: Operating Profit Trend
C5: By Month | I5: Figures in GBP millions | M5: By Month | R5: Figures in GBP millions
C30: Dashboard: Operating Margin | M30: Dashboard: Units Sold
C32: By Month | J32: Figures in % | M32: By Month | S32: Number of Units
C57: Dashboard: ASP Trend | M57: Dashboard: Revenue By Scenario
C59: By Month | I59: Figures in GBP | M59: By Scenario | Q59: Figures in GBP millions
C81: Dashboard: Operating Profit by Scenario | M81: Dashboard: Revenue Variance Bridge
C83: By Scenario | I83: Figures in GBP millions | M83: By Scenario | R83: Figures in GBP millions
C104: Dashboard: Operating Profit Variance Bridge
C106: By Scenario | I106: Figures in GBP millions
C130: Graphing Data : Timing
F132: =CHOOSE(MONTH(F133),1,1,1,2,2,2,3,3,3,4,4,4) -> 1 | G132: =CHOOSE(MONTH(G133),1,1,1,2,2,2,3,3,3,4,4,4) -> 1 | H132: =CHOOSE(MONTH(H133),1,1,1,2,2,2,3,3,3,4,4,4) -> 1 | I132: =CHOOSE(MONTH(I133),1,1,1,2,2,2,3,3,3,4,4,4) -> 2 | J132: =CHOOSE(MONTH(J133),1,1,1,2,2,2,3,3,3,4,4,4) -> 2 | K132: =CHOOSE(MONTH(K133),1,1,1,2,2,2,3,3,3,4,4,4) -> 2 | L132: =CHOOSE(MONTH(L133),1,1,1,2,2,2,3,3,3,4,4,4) -> 3 | M132: =CHOOSE(MONTH(M133),1,1,1,2,2,2,3,3,3,4,4,4) -> 3 | ... Q132: =CHOOSE(MONTH(Q133),1,1,1,2,2,2,3,3,3,4,4,4) -> 4
F133: =Forecast_Model!E13 -> 46053 | G133: =EOMONTH(F133,1) -> 46081 | H133: =EOMONTH(G133,1) -> 46112 | I133: =EOMONTH(H133,1) -> 46142 | J133: =EOMONTH(I133,1) -> 46173 | K133: =EOMONTH(J133,1) -> 46203 | L133: =EOMONTH(K133,1) -> 46234 | M133: =EOMONTH(L133,1) -> 46265 | N133: =EOMONTH(M133,1) -> 46295 | ... Q133: =EOMONTH(P133,1) -> 46387
C135: Actual/Forecast
C136: 2026 | F136: =Forecast_Model!E15 -> 1 | G136: =Forecast_Model!F15 -> 1 | H136: =Forecast_Model!G15 -> 1 | I136: =Forecast_Model!H15 -> 0 | J136: =Forecast_Model!I15 -> 0 | K136: =Forecast_Model!J15 -> 0 | L136: =Forecast_Model!K15 -> 0 | M136: =Forecast_Model!L15 -> 0 | ... Q136: =Forecast_Model!P15 -> 0
C137: 2027 | F137: =Forecast_Model!Q15 -> 0 | G137: =Forecast_Model!R15 -> 0 | H137: =Forecast_Model!S15 -> 0 | I137: =Forecast_Model!T15 -> 0 | J137: =Forecast_Model!U15 -> 0 | K137: =Forecast_Model!V15 -> 0 | L137: =Forecast_Model!W15 -> 0 | M137: =Forecast_Model!X15 -> 0 | ... Q137: =Forecast_Model!AB15 -> 0
C141: Graphing Data : Revenue
F143: =F$132 -> 1 | G143: =G$132 -> 1 | H143: =H$132 -> 1 | I143: =I$132 -> 2 | J143: =J$132 -> 2 | K143: =K$132 -> 2 | L143: =L$132 -> 3 | M143: =M$132 -> 3 | ... Q143: =Q$132 -> 4
F144: =F$133 -> 46053 | G144: =G$133 -> 46081 | H144: =H$133 -> 46112 | I144: =I$133 -> 46142 | J144: =J$133 -> 46173 | K144: =K$133 -> 46203 | L144: =L$133 -> 46234 | M144: =M$133 -> 46265 | ... Q144: =Q$133 -> 46387
C146: Revenue
C147: =C$136 -> 2026 | F147: =Forecast_Model!E32 -> 591600000 | G147: =Forecast_Model!F32 -> 636900000 | H147: =Forecast_Model!G32 -> 596400000 | I147: =Forecast_Model!H32 -> 600000000 | J147: =Forecast_Model!I32 -> 600000000 | K147: =Forecast_Model!J32 -> 378000000 | L147: =Forecast_Model!K32 -> 378000000 | M147: =Forecast_Model!L32 -> 378000000 | ... Q147: =Forecast_Model!P32 -> 378000000
C148: =C$137 -> 2027 | F148: =Forecast_Model!Q32 -> 385560000 | G148: =Forecast_Model!R32 -> 385560000 | H148: =Forecast_Model!S32 -> 385560000 | I148: =Forecast_Model!T32 -> 393185520 | J148: =Forecast_Model!U32 -> 4.0088448e+08 | K148: =Forecast_Model!V32 -> 4.0865688e+08 | L148: =Forecast_Model!W32 -> 416502720 | M148: =Forecast_Model!X32 -> 424422000 | ... Q148: =Forecast_Model!AB32 -> 456833520
C150: Type | D150: Labels
C151: Actuals | D151: =C$147 -> 2026 | F151: =IFERROR(F147/F$136,NA()) -> 591600000 | G151: =IFERROR(G147/G$136,NA()) -> 636900000 | H151: =IFERROR(H147/H$136,NA()) -> 596400000 | I151: =IFERROR(I147/I$136,NA()) -> #N/A | J151: =IFERROR(J147/J$136,NA()) -> #N/A | K151: =IFERROR(K147/K$136,NA()) -> #N/A | L151: =IFERROR(L147/L$136,NA()) -> #N/A | M151: =IFERROR(M147/M$136,NA()) -> #N/A | ... Q151: =IFERROR(Q147/Q$136,NA()) -> #N/A
C152: Actuals | D152: =C$148 -> 2027 | F152: =IFERROR(F148/F$137,NA()) -> #N/A | G152: =IFERROR(G148/G$137,NA()) -> #N/A | H152: =IFERROR(H148/H$137,NA()) -> #N/A | I152: =IFERROR(I148/I$137,NA()) -> #N/A | J152: =IFERROR(J148/J$137,NA()) -> #N/A | K152: =IFERROR(K148/K$137,NA()) -> #N/A | L152: =IFERROR(L148/L$137,NA()) -> #N/A | M152: =IFERROR(M148/M$137,NA()) -> #N/A | ... Q152: =IFERROR(Q148/Q$137,NA()) -> #N/A
C153: Forecast | D153: =C$147 -> 2026 | F153: =F147 -> 591600000 | G153: =G147 -> 636900000 | H153: =H147 -> 596400000 | I153: =I147 -> 600000000 | J153: =J147 -> 600000000 | K153: =K147 -> 378000000 | L153: =L147 -> 378000000 | M153: =M147 -> 378000000 | ... Q153: =Q147 -> 378000000
C154: Forecast | D154: =C$148 -> 2027 | F154: =F148 -> 385560000 | G154: =G148 -> 385560000 | H154: =H148 -> 385560000 | I154: =I148 -> 393185520 | J154: =J148 -> 4.0088448e+08 | K154: =K148 -> 4.0865688e+08 | L154: =L148 -> 416502720 | M154: =M148 -> 424422000 | ... Q154: =Q148 -> 456833520
C158: Graphing Data : Operating profit
F160: =F$132 -> 1 | G160: =G$132 -> 1 | H160: =H$132 -> 1 | I160: =I$132 -> 2 | J160: =J$132 -> 2 | K160: =K$132 -> 2 | L160: =L$132 -> 3 | M160: =M$132 -> 3 | ... Q160: =Q$132 -> 4
F161: =F$133 -> 46053 | G161: =G$133 -> 46081 | H161: =H$133 -> 46112 | I161: =I$133 -> 46142 | J161: =J$133 -> 46173 | K161: =K$133 -> 46203 | L161: =L$133 -> 46234 | M161: =M$133 -> 46265 | ... Q161: =Q$133 -> 46387
C163: Operating Profit
C164: =C$136 -> 2026 | F164: =Forecast_Model!E36 -> 66780000 | G164: =Forecast_Model!F36 -> 81914999 | H164: =Forecast_Model!G36 -> 64384278 | I164: =Forecast_Model!H36 -> 63601389 | J164: =Forecast_Model!I36 -> 61450021 | K164: =Forecast_Model!J36 -> -49092298 | L164: =Forecast_Model!K36 -> -50731180 | M164: =Forecast_Model!L36 -> -52376940 | ... Q164: =Forecast_Model!P36 -> -59029384
C165: =C$137 -> 2027 | F165: =Forecast_Model!Q36 -> -53150000 | G165: =Forecast_Model!R36 -> -54837681 | H165: =Forecast_Model!S36 -> -56532459 | I165: =Forecast_Model!T36 -> -52989749 | J165: =Forecast_Model!U36 -> -49403037 | K165: =Forecast_Model!V36 -> -45772516 | L165: =Forecast_Model!W36 -> -42098377 | M165: =Forecast_Model!X36 -> -38380813 | ... Q165: =Forecast_Model!AB36 -> -23080224
C167: Type | D167: Labels
C168: Actuals | D168: =C$147 -> 2026 | F168: =IFERROR(F164/F$136,NA()) -> 66780000 | G168: =IFERROR(G164/G$136,NA()) -> 81914999 | H168: =IFERROR(H164/H$136,NA()) -> 64384278 | I168: =IFERROR(I164/I$136,NA()) -> #N/A | J168: =IFERROR(J164/J$136,NA()) -> #N/A | K168: =IFERROR(K164/K$136,NA()) -> #N/A | L168: =IFERROR(L164/L$136,NA()) -> #N/A | M168: =IFERROR(M164/M$136,NA()) -> #N/A | ... Q168: =IFERROR(Q164/Q$136,NA()) -> #N/A
C169: Actuals | D169: =C$148 -> 2027 | F169: =IFERROR(F165/F$137,NA()) -> #N/A | G169: =IFERROR(G165/G$137,NA()) -> #N/A | H169: =IFERROR(H165/H$137,NA()) -> #N/A | I169: =IFERROR(I165/I$137,NA()) -> #N/A | J169: =IFERROR(J165/J$137,NA()) -> #N/A | K169: =IFERROR(K165/K$137,NA()) -> #N/A | L169: =IFERROR(L165/L$137,NA()) -> #N/A | M169: =IFERROR(M165/M$137,NA()) -> #N/A | ... Q169: =IFERROR(Q165/Q$137,NA()) -> #N/A
C170: Forecast | D170: =C$147 -> 2026 | F170: =F164 -> 66780000 | G170: =G164 -> 81914999 | H170: =H164 -> 64384278 | I170: =I164 -> 63601389 | J170: =J164 -> 61450021 | K170: =K164 -> -49092298 | L170: =L164 -> -50731180 | M170: =M164 -> -52376940 | ... Q170: =Q164 -> -59029384
C171: Forecast | D171: =C$148 -> 2027 | F171: =F165 -> -53150000 | G171: =G165 -> -54837681 | H171: =H165 -> -56532459 | I171: =I165 -> -52989749 | J171: =J165 -> -49403037 | K171: =K165 -> -45772516 | L171: =L165 -> -42098377 | M171: =M165 -> -38380813 | ... Q171: =Q165 -> -23080224
C175: Graphing Data : Operating Margin
F177: =F$132 -> 1 | G177: =G$132 -> 1 | H177: =H$132 -> 1 | I177: =I$132 -> 2 | J177: =J$132 -> 2 | K177: =K$132 -> 2 | L177: =L$132 -> 3 | M177: =M$132 -> 3 | ... Q177: =Q$132 -> 4
...
